==================================================
2015-07-11 06:19:13,343 timed out
Traceback (most recent call last):
  File "send_to_agents.py", line 29, in run
    self.qt.getAttitude()
  File "/home/naslab/Barzin/qualisys-rt/qtm.py", line 71, in getAttitude
    self.sendCommand('GetCurrentFrame 6DEuler')
  File "/home/naslab/Barzin/qualisys-rt/qtm.py", line 116, in sendCommand
    self.sock.sendall(buf)
  File "/usr/lib/python2.7/socket.py", line 224, in meth
    return getattr(self._sock,name)(*args)
timeout: timed out
==================================================
2015-08-05 13:42:57,633 [Errno 113] No route to host
Traceback (most recent call last):
  File "send_to_agents.py", line 82, in run
    connection.sendall(msg)
  File "/usr/lib/python2.7/socket.py", line 224, in meth
    return getattr(self._sock,name)(*args)
error: [Errno 113] No route to host
==================================================
2015-08-05 16:10:08,353 [Errno 113] No route to host
Traceback (most recent call last):
  File "send_to_agents.py", line 82, in run
    connection.sendall(msg)
  File "/usr/lib/python2.7/socket.py", line 224, in meth
    return getattr(self._sock,name)(*args)
error: [Errno 113] No route to host
==================================================
2015-08-05 17:21:09,601 [Errno 113] No route to host
Traceback (most recent call last):
  File "send_to_agents.py", line 82, in run
    connection.sendall(msg)
  File "/usr/lib/python2.7/socket.py", line 224, in meth
    return getattr(self._sock,name)(*args)
error: [Errno 113] No route to host
==================================================
2015-08-05 21:28:56,513 [Errno 113] No route to host
Traceback (most recent call last):
  File "send_to_agents.py", line 82, in run
    connection.sendall(msg)
  File "/usr/lib/python2.7/socket.py", line 224, in meth
    return getattr(self._sock,name)(*args)
error: [Errno 113] No route to host
==================================================
2015-08-07 22:03:19,489 [Errno 113] No route to host
Traceback (most recent call last):
  File "send_to_agents.py", line 82, in run
    connection.sendall(msg)
  File "/usr/lib/python2.7/socket.py", line 224, in meth
    return getattr(self._sock,name)(*args)
error: [Errno 113] No route to host
==================================================
2015-08-09 17:20:34,817 [Errno 113] No route to host
Traceback (most recent call last):
  File "send_to_agents.py", line 82, in run
    connection.sendall(msg)
  File "/usr/lib/python2.7/socket.py", line 224, in meth
    return getattr(self._sock,name)(*args)
error: [Errno 113] No route to host
==================================================
2015-09-07 12:56:14,302 list index out of range
Traceback (most recent call last):
  File "send_to_agents.py", line 145, in <module>
    sendToAgent(connection, messages[agent_id], condition))
IndexError: list index out of range
==================================================
2015-10-10 22:59:20,761 [Errno 113] No route to host
Traceback (most recent call last):
  File "send_to_agents.py", line 82, in run
    connection.sendall(msg)
  File "/usr/lib/python2.7/socket.py", line 224, in meth
    return getattr(self._sock,name)(*args)
error: [Errno 113] No route to host
==================================================
2015-10-15 20:57:35,488 list index out of range
Traceback (most recent call last):
  File "send_to_agents.py", line 158, in <module>
    threads_list[-1].daemon = True
IndexError: list index out of range
==================================================
2015-10-15 20:57:35,506 [Errno 9] Bad file descriptor
Traceback (most recent call last):
  File "send_to_agents.py", line 29, in run
    self.qt.getAttitude()
  File "/home/naslab/Barzin/qualisys-rt/qtm.py", line 71, in getAttitude
    self.sendCommand('GetCurrentFrame 6DEuler')
  File "/home/naslab/Barzin/qualisys-rt/qtm.py", line 117, in sendCommand
    self.__getPacket()
  File "/home/naslab/Barzin/qualisys-rt/qtm.py", line 131, in __getPacket
    self.__parseData(data_length)
  File "/home/naslab/Barzin/qualisys-rt/qtm.py", line 168, in __parseData
    data = self.sock.recv(data_length)
  File "/usr/lib/python2.7/socket.py", line 170, in _dummy
    raise error(EBADF, 'Bad file descriptor')
error: [Errno 9] Bad file descriptor
==================================================
2015-10-15 20:58:13,606 list index out of range
Traceback (most recent call last):
  File "send_to_agents.py", line 157, in <module>
    sendToAgent(connection, messages[agent_id], condition))
IndexError: list index out of range
==================================================
2015-10-15 20:58:13,626 [Errno 9] Bad file descriptor
Traceback (most recent call last):
  File "send_to_agents.py", line 29, in run
    self.qt.getAttitude()
  File "/home/naslab/Barzin/qualisys-rt/qtm.py", line 71, in getAttitude
    self.sendCommand('GetCurrentFrame 6DEuler')
  File "/home/naslab/Barzin/qualisys-rt/qtm.py", line 117, in sendCommand
    self.__getPacket()
  File "/home/naslab/Barzin/qualisys-rt/qtm.py", line 131, in __getPacket
    self.__parseData(data_length)
  File "/home/naslab/Barzin/qualisys-rt/qtm.py", line 168, in __parseData
    data = self.sock.recv(data_length)
  File "/usr/lib/python2.7/socket.py", line 170, in _dummy
    raise error(EBADF, 'Bad file descriptor')
error: [Errno 9] Bad file descriptor
==================================================
2015-10-15 20:59:59,868 list index out of range
Traceback (most recent call last):
  File "send_to_agents.py", line 157, in <module>
    sendToAgent(connection, messages[agent_id], condition))
IndexError: list index out of range
==================================================
2015-10-15 21:01:21,334 list index out of range
Traceback (most recent call last):
  File "send_to_agents.py", line 157, in <module>
    sendToAgent(connection, messages[agent_id], condition))
IndexError: list index out of range
==================================================
2015-10-15 21:04:41,707 list assignment index out of range
Traceback (most recent call last):
  File "send_to_agents.py", line 153, in <module>
    connections_list[agent_id]=connection
IndexError: list assignment index out of range
==================================================
2015-10-15 21:05:38,701 list assignment index out of range
Traceback (most recent call last):
  File "send_to_agents.py", line 153, in <module>
    connections_list[agent_id]=connection
IndexError: list assignment index out of range
==================================================
2015-10-15 21:06:24,753 list assignment index out of range
Traceback (most recent call last):
  File "send_to_agents.py", line 153, in <module>
    connections_list[agent_id]=connection
IndexError: list assignment index out of range
==================================================
2015-10-15 21:15:26,109 name 'condition' is not defined
Traceback (most recent call last):
  File "send_to_agents.py", line 157, in <module>
    sendToAgent(connections_list[agent_id-1], messages[agent_id-1], condition))
NameError: name 'condition' is not defined
==================================================
2015-10-15 21:31:22,148 local variable 'msg' referenced before assignment
Traceback (most recent call last):
  File "send_to_agents.py", line 74, in run
    print msg
UnboundLocalError: local variable 'msg' referenced before assignment
==================================================
2015-10-15 21:31:25,316 local variable 'msg' referenced before assignment
Traceback (most recent call last):
  File "send_to_agents.py", line 74, in run
    print msg
UnboundLocalError: local variable 'msg' referenced before assignment
==================================================
2015-10-16 11:41:34,501 'list' object has no attribute 'acquire'
Traceback (most recent call last):
  File "send_to_agents.py", line 75, in run
    conditions.acquire()
AttributeError: 'list' object has no attribute 'acquire'
==================================================
2015-10-16 11:46:33,405 '_socketobject' object does not support indexing
Traceback (most recent call last):
  File "send_to_agents.py", line 83, in run
    connection[self.index].sendall(msg)
TypeError: '_socketobject' object does not support indexing
==================================================
2015-10-16 13:30:23,844 list index out of range
Traceback (most recent call last):
  File "send_to_agents.py", line 84, in run
    if messages[self.index]:
IndexError: list index out of range
==================================================
2015-10-16 13:39:58,572 unpack requires a string argument of length 4
Traceback (most recent call last):
  File "send_to_agents.py", line 84, in run
    print self.index,struct.unpack('<f', msg[1:5])[0]
error: unpack requires a string argument of length 4
==================================================
2015-10-16 13:40:28,373 unpack requires a string argument of length 4
Traceback (most recent call last):
  File "send_to_agents.py", line 87, in run
    print self.index,struct.unpack('<f', msg[1:5])[0]
error: unpack requires a string argument of length 4
==================================================
2015-10-16 13:40:46,216 unpack requires a string argument of length 4
Traceback (most recent call last):
  File "send_to_agents.py", line 87, in run
    print self.index,struct.unpack('<f', msg[1:5])[0]
error: unpack requires a string argument of length 4
==================================================
2015-10-16 20:10:36,857 [Errno 113] No route to host
Traceback (most recent call last):
  File "send_to_agents.py", line 90, in run
    connections_list[self.index].sendall(msg)
  File "/usr/lib/python2.7/socket.py", line 224, in meth
    return getattr(self._sock,name)(*args)
error: [Errno 113] No route to host
==================================================
2015-10-16 20:11:01,048 [Errno 113] No route to host
Traceback (most recent call last):
  File "send_to_agents.py", line 90, in run
    connections_list[self.index].sendall(msg)
  File "/usr/lib/python2.7/socket.py", line 224, in meth
    return getattr(self._sock,name)(*args)
error: [Errno 113] No route to host
